// start error 1
type! E1 Int // error type E1 has one constructor E1 with an Int payload

type! E2  // error type E2 has one constructor E2 with no payload

type! E3 { // error type E3 has three constructors like a normal enum type
  A
  B(Int, x~ : String)
  C(mut x~ : String, Char, y~ : Bool)
}
// end error 1

// start error 2
type! DivError String

fn div(x : Int, y : Int) -> Int!DivError {
  if y == 0 {
    raise DivError("division by zero")
  }
  x / y
}
// end error 2

impl Show for DivError with output(self, logger) {
  match self {
    DivError(e) => Show::output(e, logger)
  }
}

let signature : Unit = {
  // start error 3
  fn f() -> Unit! {
    ...
  }

  fn g!() -> Unit {
    ...
  }

  fn h() -> Unit!Error {
    ...
  }
  // end error 3

}

// start error 4
type! IntError Int

fn h(f : (Int) -> Int!, x : Int) -> Unit {
  ...
}

fn g() -> Unit {
  let _ = h(fn! { x => raise IntError(x) }, 0)
  let _ = h(fn!(x) { raise IntError(x) }, 0)

}
// end error 4

// start error 5
// Result::unwrap_or_error
fn unwrap_or_error[T, E : Error](result : Result[T, E]) -> T!E {
  match result {
    Ok(x) => x
    Err(e) => raise e
  }
}
// end error 5

test {
  (Ok(1) : Result[Int, Error]).unwrap_or_error!() |> ignore
}

// start error 6
type! E4

type! E5

fn f(e : Error) -> Unit {
  match e {
    E4 => println("E1")
    E5 => println("E2")
    _ => println("unknown error")
  }
}
// end error 6

// start error 7
fn div_reraise(x : Int, y : Int) -> Int!DivError {
  div!(x, y) // Rethrow the error if `div` raised an error
}
// end error 7

// start error 8
test {
  let res = div?(6, 3)
  inspect!(res, content="Ok(2)")
  let res = div?(6, 0)
  inspect!(
    res,
    content=
      #|Err("division by zero")
    ,
  )
}
// end error 8

test "error 9" (t : @test.T) {
  let println = fn(show) { t.writeln(show) }
  // start error 9
  try {
    div!(42, 0)
  } catch {
    DivError(s) => println(s)
  } else {
    v => println(v)
  }
  // end error 9
  t.snapshot!(filename="error_9")
}

fn error() -> Unit {
  // start error 10
  try {
    println(div!(42, 0))
  } catch {
    _ => println("Error")
  }
  // end error 10

  // start error 11
  let a = try {
    div!(42, 0)
  } catch {
    _ => 0
  }
  println(a)
  // end error 11
}

// start error 12
type T Int

type! E Int derive(Show)

fn k(self : T) -> Unit!E {
  ...
}

fn l() -> Unit!E {
  let x = T(42)
  k!(x)
  x.k!()
  x |> k!()
}
// end error 12

fn catch_() -> Unit! {
  // start error 13
  fn f1() -> Unit!E1 {
    ...
  }

  fn f2() -> Unit!E2 {
    ...
  }

  try {
    f1!()
    f2!()
  } catch {
    E1(_) => ...
    E2 => ...
    _ => ...
  }
  // end error 13
  // start error 14
  try {
    f1!()
    f2!()
  } catch! {
    E1(_) => ...
  }
  // end error 14
}
